CRITICAL:root:The piecewise candidate function was synthesized in time_synthesis0.340930700302124time_synthesis seconds
INFO:wolframclient.evaluation.kernel.kernelcontroller:Kernel writes commands to socket: <Socket: uri=tcp://127.0.0.1:42855>
INFO:wolframclient.evaluation.kernel.kernelcontroller:Kernel receives evaluated expressions from socket: <Socket: uri=tcp://127.0.0.1:34679>
INFO:wolframclient.evaluation.kernel.kernelcontroller:Kernel process started with PID: 1466714
WARNING:wolframclient.evaluation.kernel.kernelcontroller:Socket exception: Socket operation aborted.
WARNING:wolframclient.evaluation.kernel.kernelcontroller:Failed to start.
INFO:wolframclient.evaluation.kernel.kernelcontroller:Start termination on kernel <WolframKernelController[wolfram-kernel-1 ✅], "/usr/local/Wolfram/WolframEngine/13.2/Executables/WolframKernel", pid:1466714, kernel sockets: (in:tcp://127.0.0.1:34679, out:tcp://127.0.0.1:42855)>
INFO:wolframclient.evaluation.kernel.kernelcontroller:Killing kernel process: 1466714
INFO:wolframclient.evaluation.kernel.kernelcontroller:Start termination on kernel <WolframKernelController[wolfram-kernel-1 ❌], "/usr/local/Wolfram/WolframEngine/13.2/Executables/WolframKernel">
Traceback (most recent call last):
  File "/usr/local/lib/python3.8/dist-packages/wolframclient/evaluation/kernel/kernelcontroller.py", line 435, in _kernel_start
    response = self.kernel_socket_in.recv_abortable(
  File "/usr/local/lib/python3.8/dist-packages/wolframclient/evaluation/kernel/zmqsocket.py", line 50, in recv_abortable
    raise SocketAborted("Socket operation aborted.")
wolframclient.evaluation.kernel.zmqsocket.SocketAborted: Socket operation aborted.

During handling of the above exception, another exception occurred:

Traceback (most recent call last):
  File "/home/lbattista/piecewise_lyap/semialgebraic_invariants/barrier/mathematica/mathematica.py", line 75, in get_session
    MathematicaSession._session.ensure_started()
  File "/usr/local/lib/python3.8/dist-packages/wolframclient/evaluation/kernel/localsession.py", line 206, in ensure_started
    self.start(block=True, timeout=None)
  File "/usr/local/lib/python3.8/dist-packages/wolframclient/evaluation/kernel/localsession.py", line 157, in start
    raise e
  File "/usr/local/lib/python3.8/dist-packages/wolframclient/evaluation/kernel/localsession.py", line 152, in start
    future.result(timeout=timeout)
  File "/usr/lib/python3.8/concurrent/futures/_base.py", line 444, in result
    return self.__get_result()
  File "/usr/lib/python3.8/concurrent/futures/_base.py", line 389, in __get_result
    raise self._exception
  File "/usr/local/lib/python3.8/dist-packages/wolframclient/evaluation/kernel/kernelcontroller.py", line 557, in run
    self._safe_kernel_start()
  File "/usr/local/lib/python3.8/dist-packages/wolframclient/evaluation/kernel/kernelcontroller.py", line 366, in _safe_kernel_start
    raise e
  File "/usr/local/lib/python3.8/dist-packages/wolframclient/evaluation/kernel/kernelcontroller.py", line 360, in _safe_kernel_start
    self._kernel_start()
  File "/usr/local/lib/python3.8/dist-packages/wolframclient/evaluation/kernel/kernelcontroller.py", line 455, in _kernel_start
    raise WolframKernelException(
wolframclient.exception.WolframKernelException: Failed to communicate with kernel: /usr/local/Wolfram/WolframEngine/13.2/Executables/WolframKernel.

During handling of the above exception, another exception occurred:

Traceback (most recent call last):
  File "/home/lbattista/piecewise_lyap/semialgebraic_invariants/piecewise_lyap_expeval.py", line 307, in <module>
    main(args)
  File "/home/lbattista/piecewise_lyap/semialgebraic_invariants/piecewise_lyap_expeval.py", line 287, in main
    certified = certify_piecewise_lyap(dyn_systems, switching_predicate_mode0_less0, Candidate_lyap, solver = new_solver_f())
  File "/home/lbattista/piecewise_lyap/semialgebraic_invariants/barrier/mathematica/mathematica.py", line 669, in get_mathematica
    solver = MathematicaSolver(env, QF_NRA,
  File "/home/lbattista/piecewise_lyap/semialgebraic_invariants/barrier/mathematica/mathematica.py", line 141, in __init__
    self.session = MathematicaSession.get_session()
  File "/home/lbattista/piecewise_lyap/semialgebraic_invariants/barrier/mathematica/mathematica.py", line 77, in get_session
    raise SolverAPINotFound
pysmt.exceptions.SolverAPINotFound
CRITICAL:root:The piecewise candidate function was synthesized in time_synthesis0.34374499320983887time_synthesis seconds
CRITICAL:root:The piecewise candidate function was synthesized in time_synthesis0.3384566307067871time_synthesis seconds
CRITICAL:root:The piecewise candidate function was synthesized in time_synthesis0.34052062034606934time_synthesis seconds
INFO:wolframclient.evaluation.kernel.kernelcontroller:Kernel writes commands to socket: <Socket: uri=tcp://127.0.0.1:46093>
INFO:wolframclient.evaluation.kernel.kernelcontroller:Kernel receives evaluated expressions from socket: <Socket: uri=tcp://127.0.0.1:39131>
INFO:wolframclient.evaluation.kernel.kernelcontroller:Kernel writes commands to socket: <Socket: uri=tcp://127.0.0.1:33051>
INFO:wolframclient.evaluation.kernel.kernelcontroller:Kernel writes commands to socket: <Socket: uri=tcp://127.0.0.1:42687>
INFO:wolframclient.evaluation.kernel.kernelcontroller:Kernel receives evaluated expressions from socket: <Socket: uri=tcp://127.0.0.1:34393>
INFO:wolframclient.evaluation.kernel.kernelcontroller:Kernel receives evaluated expressions from socket: <Socket: uri=tcp://127.0.0.1:43559>
INFO:wolframclient.evaluation.kernel.kernelcontroller:Kernel process started with PID: 1466752
INFO:wolframclient.evaluation.kernel.kernelcontroller:Kernel process started with PID: 1466764
INFO:wolframclient.evaluation.kernel.kernelcontroller:Kernel process started with PID: 1466765
WARNING:wolframclient.evaluation.kernel.kernelcontroller:Socket exception: Socket operation aborted.
WARNING:wolframclient.evaluation.kernel.kernelcontroller:Failed to start.
INFO:wolframclient.evaINFO:wolframclient.evaluation.kernel.kernelcontroller:Kernel process started with PID: 1522995
CRITICAL:root:The piecewise candidate function was synthesized in time_synthesis0.3354003429412842time_synthesis seconds
INFO:wolframclient.evaluation.kernel.kernelcontroller:Kernel writes commands to socket: <Socket: uri=tcp://127.0.0.1:42641>
INFO:wolframclient.evaluation.kernel.kernelcontroller:Kernel receives evaluated expressions from socket: <Socket: uri=tcp://127.0.0.1:35281>
local/Wolfram/WolframEngine/13.2/Executables/WolframKernel">
WARNING:wolframclient.evaluation.kernel.kernelcontroller:Socket exception: Socket operation aborted.
WARNING:wolframclient.evaluation.kernel.kernelcontroller:Socket exception: Socket operation aborted.
WARNING:wolframclient.evaluation.kernel.kernelcontroller:Failed to start.
WARNING:wolframclient.evaluation.kernel.kernelcontroller:Failed to start.
INFO:wolframclient.evaluation.kernel.kernelcontroller:Start termination on kernel <WolframKernelController[wolfram-kernel-1 ✅], "/usr/local/Wolfram/WolframEngine/13.2/Executables/WolframKernel", pid:1466764, kernel sockets: (in:tcp://127.0.0.1:43559, out:tcp://127.0.0.1:42687)>
INFO:wolframclient.evaluation.kernel.kernelcontroller:Start termination on kernel <WolframKernelController[wolfram-kernel-1 ✅], "/usr/local/Wolfram/WolframEngine/13.2/Executables/WolframKernel", pid:1466765, kernel sockets: (in:tcp://127.0.0.1:34393, out:tcp://127.0.0.1:33051)>
Traceback (most recent call last):
  File "/usr/local/lib/python3.8/dist-packages/wolframclient/evaluation/kernel/kernelcontroller.py", line 435, in _kernel_start
    response = self.kernel_socket_in.recv_abortable(
  File "/usr/local/lib/python3.8/dist-packages/wolframclient/evaluation/kernel/zmqsocket.py", line 50, in recv_abortable
    raise SocketAborted("Socket operation aborted.")
wolframclient.evaluation.kernel.zmqsocket.SocketAborted: Socket operation aborted.

During handling of the above exception, another exception occurred:

Traceback (most recent call last):
  File "/home/lbattista/piecewise_lyap/semialgebraic_invariants/barrier/mathematica/mathematica.py", line 75, in get_session
    MathematicaSession._session.ensure_started()
  File "/usr/local/lib/python3.8/dist-packages/wolframclient/evaluation/kernel/localsession.py", line 206, in ensure_started
    self.start(block=True, timeout=None)
  File "/usr/local/lib/python3.8/dist-packages/wolframclient/evaluation/kernel/localsession.py", line 157, in start
    raise e
  File "/usr/local/lib/python3.8/dist-packages/wolframclient/evaluation/kernel/localsession.py", line 152, in start
    future.result(timeout=timeout)
  File "/usr/lib/python3.8/concurrent/futures/_base.py", line 444, in result
    return self.__get_result()
  File "/usr/lib/python3.8/concurrent/futures/_base.py", line 389, in __get_result
    raise self._exception
  File "/usr/local/lib/python3.8/dist-packages/wolframclient/evaluation/kernel/kernelcontroller.py", line 557, in run
    self._safe_kernel_start()
  File "/usr/local/lib/python3.8/dist-packages/wolframclient/evaluation/kernel/kernelcontroller.py", line 366, in _safe_kernel_start
    raise e
  File "/usr/local/lib/python3.8/dist-packages/wolframclient/evaluation/kernel/kernelcontroller.py", line 360, in _safe_kernel_start
    self._kernel_start()
  File "/usr/local/lib/python3.8/dist-packages/wolframclient/evaluation/kernel/kernelcontroller.py", line 455, in _kernel_start
    raise WolframKernelException(
wolframclient.exception.WolframKernelException: Failed to communicate with kernel: /usr/local/Wolfram/WolframEngine/13.2/Executables/WolframKernel.

During handling of the above exception, another exception occurred:

Traceback (most recent call last):
  File "/home/lbattista/piecewise_lyap/semialgebraic_invariants/piecewise_lyap_expeval.py", line 307, in <module>
    main(args)
  File "/home/lbattista/piecewise_lyap/semialgebraic_invariants/piecewise_lyap_expeval.py", line 287, in main
    certified = certify_piecewise_lyap(dyn_systems, switching_predicate_mode0_less0, Candidate_lyap, solver = new_solver_f())
  File "/home/lbattista/piecewise_lyap/semialgebraic_invariants/barrier/mathematica/mathematica.py", line 669, in get_mathematica
    solver = MathematicaSolver(env, QF_NRA,
  File "/home/lbattista/piecewise_lyap/semialgebraic_invariants/barrier/mathematica/mathematica.py", line 141, in __init__
    self.session = MathematicaSession.get_session()
  File "/home/lbattista/piecewise_lyap/semialgebraic_invariants/barrier/mathematica/mathematica.py", line 77, in get_session
    raise SolverAPINotFound
pysmt.exceptions.SolverAPINotFound
INFO:wolframclient.evaluation.kernel.kernelcontroller:Killing kernel process: 1466764
INFO:wolframclient.evaluation.kernel.kernelcontroller:Killing kernel process: 1466765
INFO:wolframclient.evaluation.kernel.kernelcontroller:Start termination on kernel <WolframKernelController[wolfram-kernel-1 ❌], "/usr/local/Wolfram/WolframEngine/13.2/Executables/WolframKernel">
INFO:wolframclient.evaluation.kernel.kernelcontroller:Start termination on kernel <WolframKernelController[wolfram-kernel-1 ❌], "/usr/local/Wolfram/WolframEngine/13.2/Executables/WolframKernel">
Traceback (most recent call last):
  File "/usr/local/lib/python3.8/dist-packages/wolframclient/evaluation/kernel/kernelcontroller.py", line 435, in _kernel_start
    response = self.kernel_socket_in.recv_abortable(
  File "/usr/local/lib/python3.8/dist-packages/wolframclient/evaluation/kernel/zmqsocket.py", line 50, in recv_abortable
    raise SocketAborted("Socket operation aborted.")
wolframclient.evaluation.kernel.zmqsocket.SocketAborted: Socket operation aborted.

During handling of the above exception, another exception occurred:

Traceback (most recent call last):
  File "/home/lbattista/piecewise_lyap/semialgebraic_invariants/barrier/mathematica/mathematica.py", line 75, in get_session
    MathematicaSession._session.ensure_started()
  File "/usr/local/lib/python3.8/dist-packages/wolframclient/evaluation/kernel/localsession.py", line 206, in ensure_started
    self.start(block=True, timeout=None)
  File "/usr/local/lib/python3.8/dist-packages/wolframclient/evaluation/kernel/localsession.py", line 157, in start
    raise e
  File "/usr/local/lib/python3.8/dist-packages/wolframclient/evaluation/kernel/localsession.py", line 152, in start
    future.result(timeout=timeout)
  File "/usr/lib/python3.8/concurrent/futures/_base.py", line 444, in result
    return self.__get_result()
  File "/usr/lib/python3.8/concurrent/futures/_base.py", line 389, in __get_result
    raise self._exception
  File "/usr/local/lib/python3.8/dist-packages/wolframclient/evaluation/kernel/kernelcontroller.py", line 557, in run
    self._safe_kernel_start()
  File "/usr/local/lib/python3.8/dist-packages/wolframclient/evaluation/kernel/kernelcontroller.py", line 366, in _safe_kernel_start
    raise e
  File "/usr/local/lib/python3.8/dist-packages/wolframclient/evaluation/kernel/kernelcontroller.py", line 360, in _safe_kernel_start
    self._kernel_start()
  File "/usr/local/lib/python3.8/dist-packages/wolframclient/evaluation/kernel/kernelcontroller.py", line 455, in _kernel_start
    raise WolframKernelException(
wolframclient.exception.WolframKernelException: Failed to communicate with kernel: /usr/local/Wolfram/WolframEngine/13.2/Executables/WolframKernel.

During handling of the above exception, another exception occurred:

Traceback (most recent call last):
  File "/home/lbattista/piecewise_lyap/semialgebraic_invariants/piecewise_lyap_expeval.py", line 307, in <module>
    main(args)
  File "/home/lbattista/piecewise_lyap/semialgebraic_invariants/piecewise_lyap_expeval.py", line 287, in main
    certified = certify_piecewise_lyap(dyn_systems, switching_predicate_mode0_less0, Candidate_lyap, solver = new_solver_f())
  File "/home/lbattista/piecewise_lyap/semialgebraic_invariants/barrier/mathematica/mathematica.py", line 669, in get_mathematica
    solver = MathematicaSolver(env, QF_NRA,
  File "/home/lbattista/piecewise_lyap/semialgebraic_invariants/barrier/mathematica/mathematica.py", line 141, in __init__
    self.session = MathematicaSession.get_session()
  File "/home/lbattista/piecewise_lyap/semialgebraic_invariants/barrier/mathematica/mathematica.py", line 77, in get_session
    raise SolverAPINotFound
pysmt.exceptions.SolverAPINotFound
Traceback (most recent call last):
  File "/usr/local/lib/python3.8/dist-packages/wolframclient/evaluation/kernel/kernelcontroller.py", line 435, in _kernel_start
    response = self.kernel_socket_in.recv_abortable(
  File "/usr/local/lib/python3.8/dist-packages/wolframclient/evaluation/kernel/zmqsocket.py", line 50, in recv_abortable
    raise SocketAborted("Socket operation aborted.")
wolframclient.evaluation.kernel.zmqsocket.SocketAborted: Socket operation aborted.

During handling of the above exception, another exception occurred:

Traceback (most recent call last):
  File "/home/lbattista/piecewise_lyap/semialgebraic_invariants/barrier/mathematica/mathematica.py", line 75, in get_session
    MathematicaSession._session.ensure_started()
  File "/usr/local/lib/python3.8/dist-packages/wolframclient/evaluation/kernel/localsession.py", line 206, in ensure_started
    self.start(block=True, timeout=None)
  File "/usr/local/lib/python3.8/dist-packages/wolframclient/evaluation/kernel/localsession.py", line 157, in start
    raise e
  File "/usr/local/lib/python3.8/dist-packages/wolframclient/evaluation/kernel/localsession.py", line 152, in start
    future.result(timeout=timeout)
  File "/usr/lib/python3.8/concurrent/futures/_base.py", line 444, in result
    return self.__get_result()
  File "/usr/lib/python3.8/concurrent/futures/_base.py", line 389, in __get_result
    raise self._exception
  File "/usr/local/lib/python3.8/dist-packages/wolframclient/evaluation/kernel/kernelcontroller.py", line 557, in run
    self._safe_kernel_start()
  File "/usr/local/lib/python3.8/dist-packages/wolframclient/evaluation/kernel/kernelcontroller.py", line 366, in _safe_kernel_start
    raise e
  File "/usr/local/lib/python3.8/dist-packages/wolframclient/evaluation/kernel/kernelcontroller.py", line 360, in _safe_kernel_start
    self._kernel_start()
  File "/usr/local/lib/python3.8/dist-packages/wolframclient/evaluation/kernel/kernelcontroller.py", line 455, in _kernel_start
    raise WolframKernelException(
wolframclient.exception.WolframKernelException: Failed to communicate with kernel: /usr/local/Wolfram/WolframEngine/13.2/Executables/WolframKernel.

During handling of the above exception, another exception occurred:

Traceback (most recent call last):
  File "/home/lbattista/piecewise_lyap/semialgebraic_invariants/piecewise_lyap_expeval.py", line 307, in <module>
    main(args)
  File "/home/lbattista/piecewise_lyap/semialgebraic_invariants/piecewise_lyap_expeval.py", line 287, in main
    certified = certify_piecewise_lyap(dyn_systems, switching_predicate_mode0_less0, Candidate_lyap, solver = new_solver_f())
  File "/home/lbattista/piecewise_lyap/semialgebraic_invariants/barrier/mathematica/mathematica.py", line 669, in get_mathematica
    solver = MathematicaSolver(env, QF_NRA,
  File "/home/lbattista/piecewise_lyap/semialgebraic_invariants/barrier/mathematica/mathematica.py", line 141, in __init__
    self.session = MathematicaSession.get_session()
  File "/home/lbattista/piecewise_lyap/semialgebraic_invariants/barrier/mathematica/mathematica.py", line 77, in get_session
    raise SolverAPINotFound
pysmt.exceptions.SolverAPINotFound
INFO:wolframclient.evaluation.kernel.kernelcontroller:Kernel process started with PID: 1523021
INFO:wolframclient.evaluation.kernel.kernelcontroller:Kernel 1522995 is ready. Startup took 2.38 seconds.
WARNING:wolframclient.evaluation.kernel.kernelcontroller:Socket exception: Socket operation aborted.
WARNING:wolframclient.evaluation.kernel.kernelcontroller:Failed to start.
INFO:wolframclient.evaluation.kernel.kernelcontroller:Start termination on kernel <WolframKernelController[wolfram-kernel-1 ✅], "/usr/local/Wolfram/WolframEngine/13.2/Executables/WolframKernel", pid:1523021, kernel sockets: (in:tcp://127.0.0.1:35281, out:tcp://127.0.0.1:42641)>
INFO:wolframclient.evaluation.kernel.kernelcontroller:Killing kernel process: 1523021
INFO:wolframclient.evaluation.kernel.kernelcontroller:Start termination on kernel <WolframKernelController[wolfram-kernel-1 INFO:wolframclient.evaluation.kernel.kernelcontroller:Kernel process started with PID: 1442695
CRITICAL:root:The piecewise candidate function was synthesized in time_synthesis0.30516862869262695time_synthesis seconds
INFO:wolframclient.evaluation.kernel.kernelcontroller:Kernel writes commands to socket: <Socket: uri=tcp://127.0.0.1:38281>
INFO:wolframclient.evaluation.kernel.kernelcontroller:Kernel receives evaluated expressions from socket: <Socket: uri=tcp://127.0.0.1:36333>
ation.kernel.zmqsocket.SocketAborted: Socket operation aborted.

During handling of the above exception, another exception occurred:

Traceback (most recent call last):
  File "/home/lbattista/piecewise_lyap/semialgebraic_invariants/barrier/mathematica/mathematica.py", line 75, in get_session
    MathematicaSession._session.ensure_started()
  File "/usr/local/lib/python3.8/dist-packages/wolframclient/evaluation/kernel/localsession.py", line 206, in ensure_started
    self.start(block=True, timeout=None)
  File "/usr/local/lib/python3.8/dist-packages/wolframclient/evaluation/kernel/localsession.py", line 157, in start
    raise e
  File "/usr/local/lib/python3.8/dist-packages/wolframclient/evaluation/kernel/localsession.py", line 152, in start
    future.result(timeout=timeout)
  File "/usr/lib/python3.8/concurrent/futures/_base.py", line 444, in result
    return self.__get_result()
  File "/usr/lib/python3.8/concurrent/futures/_base.py", line 389, in __get_result
    raise self._exception
  File "/usr/local/lib/python3.8/dist-packages/wolframclient/evaluation/kernel/kernelcontroller.py", line 557, in run
    self._safe_kernel_start()
  File "/usr/local/lib/python3.8/dist-packages/wolframclient/evaluation/kernel/kernelcontroller.py", line 366, in _safe_kernel_start
    raise e
  File "/usr/local/lib/python3.8/dist-packages/wolframclient/evaluation/kernel/kernelcontroller.py", line 360, in _safe_kernel_start
    self._kernel_start()
  File "/usr/local/lib/python3.8/dist-packages/wolframclient/evaluation/kernel/kernelcontroller.py", line 455, in _kernel_start
    raise WolframKernelException(
wolframclient.exception.WolframKernelException: Failed to communicate with kernel: /usr/local/Wolfram/WolframEngine/13.2/Executables/WolframKernel.

During handling of the above exception, another exception occurred:

Traceback (most recent call last):
  File "/home/lbattista/piecewise_lyap/semialgebraic_invariants/piecewise_lyap_expeval.py", line 307, in <module>
    main(args)
  File "/home/lbattista/piecewise_lyap/semialgebraic_invariants/piecewise_lyap_expeval.py", line 287, in main
    certified = certify_piecewise_lyap(dyn_systems, switching_predicate_mode0_less0, Candidate_lyap, solver = new_solver_f())
  File "/home/lbattista/piecewise_lyap/semialgebraic_invariants/barrier/mathematica/mathematica.py", line 669, in get_mathematica
    solver = MathematicaSolver(env, QF_NRA,
  File "/home/lbattista/piecewise_lyap/semialgebraic_invariants/barrier/mathematica/mathematica.py", line 141, in __init__
    self.session = MathematicaSession.get_session()
  File "/home/lbattista/piecewise_lyap/semialgebraic_invariants/barrier/mathematica/mathematica.py", line 77, in get_session
    raise SolverAPINotFound
pysmt.exceptions.SolverAPINotFound
INFO:wolframclient.evaluation.kernel.kernelcontroller:Kernel process started with PID: 1442735
WARNING:wolframclient.evaluation.kernel.kernelcontroller:Socket exception: Socket operation aborted.
WARNING:wolframclient.evaluation.kernel.kernelcontroller:Failed to start.
INFO:wolframclient.evaluation.kernel.kernelcontroller:Start termination on kernel <WolframKernelController[wolfram-kernel-1 ✅], "/usr/local/Wolfram/WolframEngine/13.2/Executables/WolframKernel", pid:1442735, kernel sockets: (in:tcp://127.0.0.1:36333, out:tcp://127.0.0.1:38281)>
INFO:wolframclient.evaluation.kernel.kernelcontroller:Killing kernel process: 1442735
INFO:wolframclient.evaluation.kernel.kernelcontroller:Start termination on kernel <WolframKernelController[wolfram-kernel-1 ❌], "/usr/local/Wolfram/WolframEngine/13.2/Executables/WolframKernel">
Traceback (most recent call last):
  File "/usr/local/lib/python3.8/dist-packages/wolframclient/evaluation/kernel/kernelcontroller.py", line 435, in _kernel_start
    response = self.kernel_socket_in.recv_abortable(
  File "/usr/local/lib/python3.8/dist-packages/wolframclient/evaluation/kernel/zmqsocket.py", line 50, in recv_abortable
    raise SocketAborted("Socket operation aborted.")
wolframclient.evaluation.kernel.zmqsocket.SocketAborted: Socket operation aborted.

During handling of the above exception, another exception occurred:

Traceback (most recent call last):
  File "/home/lbattista/piecewise_lyap/semialgebraic_invariants/barrier/mathematica/mathematica.py", line 75, in get_session
    MathematicaSession._session.ensure_started()
  File "/usr/local/lib/python3.8/dist-packages/wolframclient/evaluation/kernel/localsession.py", line 206, in ensure_started
    self.start(block=True, timeout=None)
  File "/usr/local/lib/python3.8/dist-packages/wolframclient/evaluation/kernel/localsession.py", line 157, in start
    raise e
  File "/usr/local/lib/python3.8/dist-packages/wolframclient/evaluation/kernel/localsession.py", line 152, in start
    future.result(timeout=timeout)
  File "/usr/lib/python3.8/concurrent/futures/_base.py", line 444, in result
    return self.__get_result()
  File "/usr/lib/python3.8/concurrent/futures/_base.py", line 389, in __get_result
    raise self._exception
  File "/usr/local/lib/python3.8/dist-packages/wolframclient/evaluation/kernel/kernelcontroller.py", line 557, in run
    self._safe_kernel_start()
  File "/usr/local/lib/python3.8/dist-packages/wolframclient/evaluation/kernel/kernelcontroller.py", line 366, in _safe_kernel_start
    raise e
  File "/usr/local/lib/python3.8/dist-packages/wolframclient/evaluation/kernel/kernelcontroller.py", line 360, in _safe_kernel_start
    self._kernel_start()
  File "/usr/local/lib/python3.8/dist-packages/wolframclient/evaluation/kernel/kernelcontroller.py", line 455, in _kernel_start
    raise WolframKernelException(
wolframclient.exception.WolframKernelException: Failed to communicate with kernel: /usr/local/Wolfram/WolframEngine/13.2/Executables/WolframKernel.

During handling of the above exception, another exception occurred:

Traceback (most recent call last):
  File "/home/lbattista/piecewise_lyap/semialgebraic_invariants/piecewise_lyap_expeval.py", line 307, in <module>
    main(args)
  File "/home/lbattista/piecewise_lyap/semialgebraic_invariants/piecewise_lyap_expeval.py", line 287, in main
    certified = certify_piecewise_lyap(dyn_systems, switching_predicate_mode0_less0, Candidate_lyap, solver = new_solver_f())
  File "/home/lbattista/piecewise_lyap/semialgebraic_invariants/barrier/mathematica/mathematica.py", line 669, in get_mathematica
    solver = MathematicaSolver(env, QF_NRA,
  File "/home/lbattista/piecewise_lyap/semialgebraic_invariants/barrier/mathematica/mathematica.py", line 141, in __init__
    self.session = MathematicaSession.get_session()
  File "/home/lbattista/piecewise_lyap/semialgebraic_invariants/barrier/mathematica/mathematica.py", line 77, in get_session
    raise SolverAPINotFound
pysmt.exceptions.SolverAPINotFound
CRITICAL:root:The piecewise candidate function was synthesized in time_synthesis0.30254435539245605time_synthesis seconds
INFO:wolframclient.evaluation.kernel.kernelcontroller:Kernel writes commands to socket: <Socket: uri=tcp://127.0.0.1:38703>
INFO:wolframclient.evaluation.kernel.kernelcontroller:Kernel receives evaluated expressions from socket: <Socket: uri=tcp://127.0.0.1:34049>
INFO:wolframclient.evaluation.kernel.kernelcontroller:Kernel process started with PID: 1442760
WARNING:wolframclient.evaluation.kernel.kernelcontroller:Socket exception: Socket operation aborted.
WARNING:wolframclient.evaluation.kernel.kernelcontroller:Failed to start.
INFO:wolframclient.evaluation.kernel.kernelcontroller:Start termination on kernel <WolframKernelController[wolfram-kernel-1 ✅], "/usr/local/Wolfram/WolframEngine/13.2/Executables/WolframKernel", pid:1442760, kernel sockets: (in:tcp://127.0.0.1:34049, out:tcp://127.0.0.1:38703)>
INFO:wolframclient.evaluation.kernel.kernelcontroller:Killing kernel process: 1442760
INFO:wolframclient.evaluation.kernel.kernelcontroller:Start termination on kernel <WolframKernelController[wolfram-kernel-1 ❌], "/usr/local/Wolfram/WolframEngine/13.2/Executables/WolframKernel">
Traceback (most recent call last):
  File "/usr/local/lib/python3.8/dist-packages/wolframclient/evaluation/kernel/kernelcontroller.py", line 435, in _kernel_start
    response = self.kernel_socket_in.recv_abortable(
  File "/usr/local/lib/python3.8/dist-packages/wolframclient/evaluation/kernel/zmqsocket.py", line 50, in recv_abortable
    raise SocketAborted("Socket operation aborted.")
wolframclient.evaluation.kernel.zmqsocket.SocketAborted: Socket operation aborted.

During handling of the above exception, another exception occurred:

Traceback (most recent call last):
  File "/home/lbattista/piecewise_lyap/semialgebraic_invariants/barrier/mathematica/mathematica.py", line 75, in get_session
    MathematicaSession._session.ensure_started()
  File "/usr/local/lib/python3.8/dist-packages/wolframclient/evaluation/kernel/localsession.py", line 206, in ensure_started
    self.start(block=True, timeout=None)
  File "/usr/local/lib/python3.8/dist-packages/wolframclient/evaluation/kernel/localsession.py", line 157, in start
    raise e
  File "/usr/local/lib/python3.8/dist-packages/wolframclient/evaluation/kernel/localsession.py", line 152, in start
    future.result(timeout=timeout)
  File "/usr/lib/python3.8/concurrent/futures/_base.py", line 444, in result
    return self.__get_result()
  File "/usr/lib/python3.8/concurrent/futures/_base.py", line 389, in __get_result
    raise self._exception
  File "/usr/local/lib/python3.8/dist-packages/wolframclient/evaluation/kernel/kernelcontroller.py", line 557, in run
    self._safe_kernel_start()
  File "/usr/local/lib/python3.8/dist-packages/wolframclient/evaluation/kernel/kernelcontroller.py", line 366, in _safe_kernel_start
    raise e
  File "/usr/local/lib/python3.8/dist-packages/wolframclient/evaluation/kernel/kernelcontroller.py", line 360, in _safe_kernel_start
    self._kernel_start()
  File "/usr/local/lib/python3.8/dist-packages/wolframclient/evaluation/kernel/kernelcontroller.py", line 455, in _kernel_start
    raise WolframKernelException(
wolframclient.exception.WolframKernelException: Failed to communicate with kernel: /usr/local/Wolfram/WolframEngine/13.2/Executables/WolframKernel.

During handling of the above exception, another exception occurred:

Traceback (most recent call last):
  File "/home/lbattista/piecewise_lyap/semialgebraic_invariants/piecewise_lyap_expeval.py", line 307, in <module>
    main(args)
  File "/home/lbattista/piecewise_lyap/semialgebraic_invariants/piecewise_lyap_expeval.py", line 287, in main
    certified = certify_piecewise_lyap(dyn_systems, switching_predicate_mode0_less0, Candidate_lyap, solver = new_solver_f())
  File "/home/lbattista/piecewise_lyap/semialgebraic_invariants/barrier/mathematica/mathematica.py", line 669, in get_mathematica
    solver = MathematicaSolver(env, QF_NRA,
  File "/home/lbattista/piecewise_lyap/semialgebraic_invariants/barrier/mathematica/mathematica.py", line 141, in __init__
    self.session = MathematicaSession.get_session()
  File "/home/lbattista/piecewise_lyap/semialgebraic_invariants/barrier/mathematica/mathematica.py", line 77, in get_session
    raise SolverAPINotFound
pysmt.exceptions.SolverAPINotFound
INFO:wolframclient.evaluation.kernel.kernelcontroller:Kernel 1442686 is ready. Startup took 2.27 seconds.
INFO:wolframclient.evaluation.kernel.kernelcontroller:Kernel 1442695 is ready. Startup took 2.45 seconds.
slurmstepd-node58: error: *** JOB 3752035 ON node58 CANCELLED AT 2023-07-17T15:37:35 ***
slurmstepd-node70: error: *** JOB 3752037 ON node70 CANCELLED AT 2023-07-17T15:37:39 ***
CRITICAL:root:CHECK Lyap m0 is everywhere positive
CRITICAL:root:CHECK Lyap m1 is everywhere positive
