CRITICAL:root:The piecewise candidate function was synthesized in time_synthesis1.9885313510894775time_synthesis seconds
INFO:wolframclient.evaluation.kernel.kernelcontroller:Kernel writes commands to socket: <Socket: uri=tcp://127.0.0.1:43163>
INFO:wolframclient.evaluation.kernel.kernelcontroller:Kernel receives evaluated expressions from socket: <Socket: uri=tcp://127.0.0.1:40481>
INFO:wolframclient.evaluation.kernel.kernelcontroller:Kernel process started with PID: 1520654
WARNING:wolframclient.evaluation.kernel.kernelcontroller:Socket exception: Failed to read any message from socket tcp://127.0.0.1:40481 after 20.0 seconds and 200 retries.
WARNING:wolframclient.evaluation.kernel.kernelcontroller:Failed to start.
INFO:wolframclient.evaluation.kernel.kernelcontroller:Start termination on kernel <WolframKernelController[wolfram-kernel-1 ✅], "/usr/local/Wolfram/WolframEngine/13.2/Executables/WolframKernel", pid:1520654, kernel sockets: (in:tcp://127.0.0.1:40481, out:tcp://127.0.0.1:43163)>
INFO:wolframclient.evaluation.kernel.kernelcontroller:Killing kernel process: 1520654
INFO:wolframclient.evaluation.kernel.kernelcontroller:Start termination on kernel <WolframKernelController[wolfram-kernel-1 ❌], "/usr/local/Wolfram/WolframEngine/13.2/Executables/WolframKernel">
Traceback (most recent call last):
  File "/usr/local/lib/python3.8/dist-packages/wolframclient/evaluation/kernel/kernelcontroller.py", line 435, in _kernel_start
    response = self.kernel_socket_in.recv_abortable(
  File "/usr/local/lib/python3.8/dist-packages/wolframclient/evaluation/kernel/zmqsocket.py", line 53, in recv_abortable
    raise SocketOperationTimeout(
wolframclient.evaluation.kernel.zmqsocket.SocketOperationTimeout: Failed to read any message from socket tcp://127.0.0.1:40481 after 20.0 seconds and 200 retries.

During handling of the above exception, another exception occurred:

Traceback (most recent call last):
  File "/home/lbattista/piecewise_lyap/semialgebraic_invariants/barrier/mathematica/mathematica.py", line 75, in get_session
    MathematicaSession._session.ensure_started()
  File "/usr/local/lib/python3.8/dist-packages/wolframclient/evaluation/kernel/localsession.py", line 206, in ensure_started
    self.start(block=True, timeout=None)
  File "/usr/local/lib/python3.8/dist-packages/wolframclient/evaluation/kernel/localsession.py", line 157, in start
    raise e
  File "/usr/local/lib/python3.8/dist-packages/wolframclient/evaluation/kernel/localsession.py", line 152, in start
    future.result(timeout=timeout)
  File "/usr/lib/python3.8/concurrent/futures/_base.py", line 444, in result
    return self.__get_result()
  File "/usr/lib/python3.8/concurrent/futures/_base.py", line 389, in __get_result
    raise self._exception
  File "/usr/local/lib/python3.8/dist-packages/wolframclient/evaluation/kernel/kernelcontroller.py", line 557, in run
    self._safe_kernel_start()
  File "/usr/local/lib/python3.8/dist-packages/wolframclient/evaluation/kernel/kernelcontroller.py", line 366, in _safe_kernel_start
    raise e
  File "/usr/local/lib/python3.8/dist-packages/wolframclient/evaluation/kernel/kernelcontroller.py", line 360, in _safe_kernel_start
    self._kernel_start()
  File "/usr/local/lib/python3.8/dist-packages/wolframclient/evaluation/kernel/kernelcontroller.py", line 455, in _kernel_start
    raise WolframKernelException(
wolframclient.exception.WolframKernelException: Failed to communicate with kernel: /usr/local/Wolfram/WolframEngine/13.2/Executables/WolframKernel.

During handling of the above exception, another exception occurred:

Traceback (most recent call last):
  File "/home/lbattista/piecewise_lyap/semialgebraic_invariants/piecewise_lyap_expeval.py", line 307, in <module>
    main(args)
  File "/home/lbattista/piecewise_lyap/semialgebraic_invariants/piecewise_lyap_expeval.py", line 287, in main
    certified = certify_piecewise_lyap(dyn_systems, switching_predicate_mode0_less0, Candidate_lyap, solver = new_solver_f())
  File "/home/lbattista/piecewise_lyap/semialgebraic_invariants/barrier/mathematica/mathematica.py", line 669, in get_mathematica
    solver = MathematicaSolver(env, QF_NRA,
  File "/home/lbattista/piecewise_lyap/semialgebraic_invariants/barrier/mathematica/mathematica.py", line 141, in __init__
    self.session = MathematicaSession.get_session()
  File "/home/lbattista/piecewise_lyap/semialgebraic_invariants/barrier/mathematica/mathematica.py", line 77, in get_session
    raise SolverAPINotFound
pysmt.exceptions.SolverAPINotFound
